<?xml version="1.0" encoding="UTF-8"?>
<testng-results skipped="0" failed="10" ignored="0" total="10" passed="0">
  <reporter-output>
  </reporter-output>
  <suite name="Regression" duration-ms="35622" started-at="2018-02-19T18:42:50Z" finished-at="2018-02-19T18:43:25Z">
    <groups>
    </groups>
    <test name="Test" duration-ms="35622" started-at="2018-02-19T18:42:50Z" finished-at="2018-02-19T18:43:25Z">
      <class name="com.alg.test.executionengine.Executor">
        <test-method status="PASS" signature="setUp()[pri:0, instance:com.alg.test.executionengine.Executor@5d624da6]" name="setUp" is-config="true" duration-ms="630" started-at="2018-02-19T13:42:49Z" finished-at="2018-02-19T13:42:50Z">
          <reporter-output>
          </reporter-output>
        </test-method> <!-- setUp -->
        <test-method status="PASS" signature="beforeClass()[pri:0, instance:com.alg.test.executionengine.Executor@5d624da6]" name="beforeClass" is-config="true" duration-ms="1318" started-at="2018-02-19T13:42:50Z" finished-at="2018-02-19T13:42:51Z">
          <reporter-output>
          </reporter-output>
        </test-method> <!-- beforeClass -->
        <test-method status="FAIL" signature="testCase(java.lang.String)[pri:0, instance:com.alg.test.executionengine.Executor@5d624da6]" name="testCase" duration-ms="7897" started-at="2018-02-19T13:42:51Z" data-provider="TestCases" finished-at="2018-02-19T13:42:59Z">
          <params>
            <param index="0">
              <value>
                <![CDATA[2]]>
              </value>
            </param>
          </params>
          <exception class="java.lang.AssertionError">
            <full-stacktrace>
              <![CDATA[java.lang.AssertionError
	at com.alg.test.executionengine.Executor.testCase(Executor.java:174)
	at sun.reflect.NativeMethodAccessorImpl.invoke0(Native Method)
	at sun.reflect.NativeMethodAccessorImpl.invoke(Unknown Source)
	at sun.reflect.DelegatingMethodAccessorImpl.invoke(Unknown Source)
	at java.lang.reflect.Method.invoke(Unknown Source)
	at org.testng.internal.MethodInvocationHelper.invokeMethod(MethodInvocationHelper.java:108)
	at org.testng.internal.Invoker.invokeMethod(Invoker.java:661)
	at org.testng.internal.Invoker.invokeTestMethod(Invoker.java:869)
	at org.testng.internal.TestMethodWithDataProviderMethodWorker.call(TestMethodWithDataProviderMethodWorker.java:75)
	at org.testng.internal.TestMethodWithDataProviderMethodWorker.call(TestMethodWithDataProviderMethodWorker.java:14)
	at java.util.concurrent.FutureTask.run(Unknown Source)
	at java.util.concurrent.Executors$RunnableAdapter.call(Unknown Source)
	at java.util.concurrent.FutureTask.run(Unknown Source)
	at java.util.concurrent.ThreadPoolExecutor.runWorker(Unknown Source)
	at java.util.concurrent.ThreadPoolExecutor$Worker.run(Unknown Source)
	at java.lang.Thread.run(Unknown Source)
]]>
            </full-stacktrace>
          </exception> <!-- java.lang.AssertionError -->
          <reporter-output>
          </reporter-output>
        </test-method> <!-- testCase -->
        <test-method status="FAIL" signature="testCase(java.lang.String)[pri:0, instance:com.alg.test.executionengine.Executor@5d624da6]" name="testCase" duration-ms="13933" started-at="2018-02-19T13:42:51Z" data-provider="TestCases" finished-at="2018-02-19T13:43:05Z">
          <params>
            <param index="0">
              <value>
                <![CDATA[1]]>
              </value>
            </param>
          </params>
          <exception class="java.lang.AssertionError">
            <full-stacktrace>
              <![CDATA[java.lang.AssertionError
	at com.alg.test.executionengine.Executor.testCase(Executor.java:174)
	at sun.reflect.NativeMethodAccessorImpl.invoke0(Native Method)
	at sun.reflect.NativeMethodAccessorImpl.invoke(Unknown Source)
	at sun.reflect.DelegatingMethodAccessorImpl.invoke(Unknown Source)
	at java.lang.reflect.Method.invoke(Unknown Source)
	at org.testng.internal.MethodInvocationHelper.invokeMethod(MethodInvocationHelper.java:108)
	at org.testng.internal.Invoker.invokeMethod(Invoker.java:661)
	at org.testng.internal.Invoker.invokeTestMethod(Invoker.java:869)
	at org.testng.internal.TestMethodWithDataProviderMethodWorker.call(TestMethodWithDataProviderMethodWorker.java:75)
	at org.testng.internal.TestMethodWithDataProviderMethodWorker.call(TestMethodWithDataProviderMethodWorker.java:14)
	at java.util.concurrent.FutureTask.run(Unknown Source)
	at java.util.concurrent.Executors$RunnableAdapter.call(Unknown Source)
	at java.util.concurrent.FutureTask.run(Unknown Source)
	at java.util.concurrent.ThreadPoolExecutor.runWorker(Unknown Source)
	at java.util.concurrent.ThreadPoolExecutor$Worker.run(Unknown Source)
	at java.lang.Thread.run(Unknown Source)
]]>
            </full-stacktrace>
          </exception> <!-- java.lang.AssertionError -->
          <reporter-output>
          </reporter-output>
        </test-method> <!-- testCase -->
        <test-method status="FAIL" signature="testCase(java.lang.String)[pri:0, instance:com.alg.test.executionengine.Executor@5d624da6]" name="testCase" duration-ms="7370" started-at="2018-02-19T13:42:51Z" data-provider="TestCases" finished-at="2018-02-19T13:42:59Z">
          <params>
            <param index="0">
              <value>
                <![CDATA[3]]>
              </value>
            </param>
          </params>
          <exception class="java.lang.AssertionError">
            <full-stacktrace>
              <![CDATA[java.lang.AssertionError
	at com.alg.test.executionengine.Executor.testCase(Executor.java:174)
	at sun.reflect.NativeMethodAccessorImpl.invoke0(Native Method)
	at sun.reflect.NativeMethodAccessorImpl.invoke(Unknown Source)
	at sun.reflect.DelegatingMethodAccessorImpl.invoke(Unknown Source)
	at java.lang.reflect.Method.invoke(Unknown Source)
	at org.testng.internal.MethodInvocationHelper.invokeMethod(MethodInvocationHelper.java:108)
	at org.testng.internal.Invoker.invokeMethod(Invoker.java:661)
	at org.testng.internal.Invoker.invokeTestMethod(Invoker.java:869)
	at org.testng.internal.TestMethodWithDataProviderMethodWorker.call(TestMethodWithDataProviderMethodWorker.java:75)
	at org.testng.internal.TestMethodWithDataProviderMethodWorker.call(TestMethodWithDataProviderMethodWorker.java:14)
	at java.util.concurrent.FutureTask.run(Unknown Source)
	at java.util.concurrent.Executors$RunnableAdapter.call(Unknown Source)
	at java.util.concurrent.FutureTask.run(Unknown Source)
	at java.util.concurrent.ThreadPoolExecutor.runWorker(Unknown Source)
	at java.util.concurrent.ThreadPoolExecutor$Worker.run(Unknown Source)
	at java.lang.Thread.run(Unknown Source)
]]>
            </full-stacktrace>
          </exception> <!-- java.lang.AssertionError -->
          <reporter-output>
          </reporter-output>
        </test-method> <!-- testCase -->
        <test-method status="FAIL" signature="testCase(java.lang.String)[pri:0, instance:com.alg.test.executionengine.Executor@5d624da6]" name="testCase" duration-ms="7166" started-at="2018-02-19T13:42:59Z" data-provider="TestCases" finished-at="2018-02-19T13:43:06Z">
          <params>
            <param index="0">
              <value>
                <![CDATA[4]]>
              </value>
            </param>
          </params>
          <exception class="java.lang.AssertionError">
            <full-stacktrace>
              <![CDATA[java.lang.AssertionError
	at com.alg.test.executionengine.Executor.testCase(Executor.java:174)
	at sun.reflect.NativeMethodAccessorImpl.invoke0(Native Method)
	at sun.reflect.NativeMethodAccessorImpl.invoke(Unknown Source)
	at sun.reflect.DelegatingMethodAccessorImpl.invoke(Unknown Source)
	at java.lang.reflect.Method.invoke(Unknown Source)
	at org.testng.internal.MethodInvocationHelper.invokeMethod(MethodInvocationHelper.java:108)
	at org.testng.internal.Invoker.invokeMethod(Invoker.java:661)
	at org.testng.internal.Invoker.invokeTestMethod(Invoker.java:869)
	at org.testng.internal.TestMethodWithDataProviderMethodWorker.call(TestMethodWithDataProviderMethodWorker.java:75)
	at org.testng.internal.TestMethodWithDataProviderMethodWorker.call(TestMethodWithDataProviderMethodWorker.java:14)
	at java.util.concurrent.FutureTask.run(Unknown Source)
	at java.util.concurrent.Executors$RunnableAdapter.call(Unknown Source)
	at java.util.concurrent.FutureTask.run(Unknown Source)
	at java.util.concurrent.ThreadPoolExecutor.runWorker(Unknown Source)
	at java.util.concurrent.ThreadPoolExecutor$Worker.run(Unknown Source)
	at java.lang.Thread.run(Unknown Source)
]]>
            </full-stacktrace>
          </exception> <!-- java.lang.AssertionError -->
          <reporter-output>
          </reporter-output>
        </test-method> <!-- testCase -->
        <test-method status="FAIL" signature="testCase(java.lang.String)[pri:0, instance:com.alg.test.executionengine.Executor@5d624da6]" name="testCase" duration-ms="7137" started-at="2018-02-19T13:42:59Z" data-provider="TestCases" finished-at="2018-02-19T13:43:06Z">
          <params>
            <param index="0">
              <value>
                <![CDATA[5]]>
              </value>
            </param>
          </params>
          <exception class="java.lang.AssertionError">
            <full-stacktrace>
              <![CDATA[java.lang.AssertionError
	at com.alg.test.executionengine.Executor.testCase(Executor.java:174)
	at sun.reflect.NativeMethodAccessorImpl.invoke0(Native Method)
	at sun.reflect.NativeMethodAccessorImpl.invoke(Unknown Source)
	at sun.reflect.DelegatingMethodAccessorImpl.invoke(Unknown Source)
	at java.lang.reflect.Method.invoke(Unknown Source)
	at org.testng.internal.MethodInvocationHelper.invokeMethod(MethodInvocationHelper.java:108)
	at org.testng.internal.Invoker.invokeMethod(Invoker.java:661)
	at org.testng.internal.Invoker.invokeTestMethod(Invoker.java:869)
	at org.testng.internal.TestMethodWithDataProviderMethodWorker.call(TestMethodWithDataProviderMethodWorker.java:75)
	at org.testng.internal.TestMethodWithDataProviderMethodWorker.call(TestMethodWithDataProviderMethodWorker.java:14)
	at java.util.concurrent.FutureTask.run(Unknown Source)
	at java.util.concurrent.Executors$RunnableAdapter.call(Unknown Source)
	at java.util.concurrent.FutureTask.run(Unknown Source)
	at java.util.concurrent.ThreadPoolExecutor.runWorker(Unknown Source)
	at java.util.concurrent.ThreadPoolExecutor$Worker.run(Unknown Source)
	at java.lang.Thread.run(Unknown Source)
]]>
            </full-stacktrace>
          </exception> <!-- java.lang.AssertionError -->
          <reporter-output>
          </reporter-output>
        </test-method> <!-- testCase -->
        <test-method status="FAIL" signature="testCase(java.lang.String)[pri:0, instance:com.alg.test.executionengine.Executor@5d624da6]" name="testCase" duration-ms="9189" started-at="2018-02-19T13:43:05Z" data-provider="TestCases" finished-at="2018-02-19T13:43:14Z">
          <params>
            <param index="0">
              <value>
                <![CDATA[6]]>
              </value>
            </param>
          </params>
          <exception class="java.lang.AssertionError">
            <full-stacktrace>
              <![CDATA[java.lang.AssertionError
	at com.alg.test.executionengine.Executor.testCase(Executor.java:174)
	at sun.reflect.NativeMethodAccessorImpl.invoke0(Native Method)
	at sun.reflect.NativeMethodAccessorImpl.invoke(Unknown Source)
	at sun.reflect.DelegatingMethodAccessorImpl.invoke(Unknown Source)
	at java.lang.reflect.Method.invoke(Unknown Source)
	at org.testng.internal.MethodInvocationHelper.invokeMethod(MethodInvocationHelper.java:108)
	at org.testng.internal.Invoker.invokeMethod(Invoker.java:661)
	at org.testng.internal.Invoker.invokeTestMethod(Invoker.java:869)
	at org.testng.internal.TestMethodWithDataProviderMethodWorker.call(TestMethodWithDataProviderMethodWorker.java:75)
	at org.testng.internal.TestMethodWithDataProviderMethodWorker.call(TestMethodWithDataProviderMethodWorker.java:14)
	at java.util.concurrent.FutureTask.run(Unknown Source)
	at java.util.concurrent.Executors$RunnableAdapter.call(Unknown Source)
	at java.util.concurrent.FutureTask.run(Unknown Source)
	at java.util.concurrent.ThreadPoolExecutor.runWorker(Unknown Source)
	at java.util.concurrent.ThreadPoolExecutor$Worker.run(Unknown Source)
	at java.lang.Thread.run(Unknown Source)
]]>
            </full-stacktrace>
          </exception> <!-- java.lang.AssertionError -->
          <reporter-output>
          </reporter-output>
        </test-method> <!-- testCase -->
        <test-method status="FAIL" signature="testCase(java.lang.String)[pri:0, instance:com.alg.test.executionengine.Executor@5d624da6]" name="testCase" duration-ms="9330" started-at="2018-02-19T13:43:06Z" data-provider="TestCases" finished-at="2018-02-19T13:43:15Z">
          <params>
            <param index="0">
              <value>
                <![CDATA[7]]>
              </value>
            </param>
          </params>
          <exception class="java.lang.AssertionError">
            <full-stacktrace>
              <![CDATA[java.lang.AssertionError
	at com.alg.test.executionengine.Executor.testCase(Executor.java:174)
	at sun.reflect.NativeMethodAccessorImpl.invoke0(Native Method)
	at sun.reflect.NativeMethodAccessorImpl.invoke(Unknown Source)
	at sun.reflect.DelegatingMethodAccessorImpl.invoke(Unknown Source)
	at java.lang.reflect.Method.invoke(Unknown Source)
	at org.testng.internal.MethodInvocationHelper.invokeMethod(MethodInvocationHelper.java:108)
	at org.testng.internal.Invoker.invokeMethod(Invoker.java:661)
	at org.testng.internal.Invoker.invokeTestMethod(Invoker.java:869)
	at org.testng.internal.TestMethodWithDataProviderMethodWorker.call(TestMethodWithDataProviderMethodWorker.java:75)
	at org.testng.internal.TestMethodWithDataProviderMethodWorker.call(TestMethodWithDataProviderMethodWorker.java:14)
	at java.util.concurrent.FutureTask.run(Unknown Source)
	at java.util.concurrent.Executors$RunnableAdapter.call(Unknown Source)
	at java.util.concurrent.FutureTask.run(Unknown Source)
	at java.util.concurrent.ThreadPoolExecutor.runWorker(Unknown Source)
	at java.util.concurrent.ThreadPoolExecutor$Worker.run(Unknown Source)
	at java.lang.Thread.run(Unknown Source)
]]>
            </full-stacktrace>
          </exception> <!-- java.lang.AssertionError -->
          <reporter-output>
          </reporter-output>
        </test-method> <!-- testCase -->
        <test-method status="FAIL" signature="testCase(java.lang.String)[pri:0, instance:com.alg.test.executionengine.Executor@5d624da6]" name="testCase" duration-ms="10521" started-at="2018-02-19T13:43:06Z" data-provider="TestCases" finished-at="2018-02-19T13:43:17Z">
          <params>
            <param index="0">
              <value>
                <![CDATA[8]]>
              </value>
            </param>
          </params>
          <exception class="java.lang.AssertionError">
            <full-stacktrace>
              <![CDATA[java.lang.AssertionError
	at com.alg.test.executionengine.Executor.testCase(Executor.java:174)
	at sun.reflect.NativeMethodAccessorImpl.invoke0(Native Method)
	at sun.reflect.NativeMethodAccessorImpl.invoke(Unknown Source)
	at sun.reflect.DelegatingMethodAccessorImpl.invoke(Unknown Source)
	at java.lang.reflect.Method.invoke(Unknown Source)
	at org.testng.internal.MethodInvocationHelper.invokeMethod(MethodInvocationHelper.java:108)
	at org.testng.internal.Invoker.invokeMethod(Invoker.java:661)
	at org.testng.internal.Invoker.invokeTestMethod(Invoker.java:869)
	at org.testng.internal.TestMethodWithDataProviderMethodWorker.call(TestMethodWithDataProviderMethodWorker.java:75)
	at org.testng.internal.TestMethodWithDataProviderMethodWorker.call(TestMethodWithDataProviderMethodWorker.java:14)
	at java.util.concurrent.FutureTask.run(Unknown Source)
	at java.util.concurrent.Executors$RunnableAdapter.call(Unknown Source)
	at java.util.concurrent.FutureTask.run(Unknown Source)
	at java.util.concurrent.ThreadPoolExecutor.runWorker(Unknown Source)
	at java.util.concurrent.ThreadPoolExecutor$Worker.run(Unknown Source)
	at java.lang.Thread.run(Unknown Source)
]]>
            </full-stacktrace>
          </exception> <!-- java.lang.AssertionError -->
          <reporter-output>
          </reporter-output>
        </test-method> <!-- testCase -->
        <test-method status="FAIL" signature="testCase(java.lang.String)[pri:0, instance:com.alg.test.executionengine.Executor@5d624da6]" name="testCase" duration-ms="10167" started-at="2018-02-19T13:43:14Z" data-provider="TestCases" finished-at="2018-02-19T13:43:24Z">
          <params>
            <param index="0">
              <value>
                <![CDATA[9]]>
              </value>
            </param>
          </params>
          <exception class="java.lang.AssertionError">
            <full-stacktrace>
              <![CDATA[java.lang.AssertionError
	at com.alg.test.executionengine.Executor.testCase(Executor.java:174)
	at sun.reflect.NativeMethodAccessorImpl.invoke0(Native Method)
	at sun.reflect.NativeMethodAccessorImpl.invoke(Unknown Source)
	at sun.reflect.DelegatingMethodAccessorImpl.invoke(Unknown Source)
	at java.lang.reflect.Method.invoke(Unknown Source)
	at org.testng.internal.MethodInvocationHelper.invokeMethod(MethodInvocationHelper.java:108)
	at org.testng.internal.Invoker.invokeMethod(Invoker.java:661)
	at org.testng.internal.Invoker.invokeTestMethod(Invoker.java:869)
	at org.testng.internal.TestMethodWithDataProviderMethodWorker.call(TestMethodWithDataProviderMethodWorker.java:75)
	at org.testng.internal.TestMethodWithDataProviderMethodWorker.call(TestMethodWithDataProviderMethodWorker.java:14)
	at java.util.concurrent.FutureTask.run(Unknown Source)
	at java.util.concurrent.Executors$RunnableAdapter.call(Unknown Source)
	at java.util.concurrent.FutureTask.run(Unknown Source)
	at java.util.concurrent.ThreadPoolExecutor.runWorker(Unknown Source)
	at java.util.concurrent.ThreadPoolExecutor$Worker.run(Unknown Source)
	at java.lang.Thread.run(Unknown Source)
]]>
            </full-stacktrace>
          </exception> <!-- java.lang.AssertionError -->
          <reporter-output>
          </reporter-output>
        </test-method> <!-- testCase -->
        <test-method status="FAIL" signature="testCase(java.lang.String)[pri:0, instance:com.alg.test.executionengine.Executor@5d624da6]" name="testCase" duration-ms="9548" started-at="2018-02-19T13:43:15Z" data-provider="TestCases" finished-at="2018-02-19T13:43:25Z">
          <params>
            <param index="0">
              <value>
                <![CDATA[10]]>
              </value>
            </param>
          </params>
          <exception class="java.lang.AssertionError">
            <full-stacktrace>
              <![CDATA[java.lang.AssertionError
	at com.alg.test.executionengine.Executor.testCase(Executor.java:174)
	at sun.reflect.NativeMethodAccessorImpl.invoke0(Native Method)
	at sun.reflect.NativeMethodAccessorImpl.invoke(Unknown Source)
	at sun.reflect.DelegatingMethodAccessorImpl.invoke(Unknown Source)
	at java.lang.reflect.Method.invoke(Unknown Source)
	at org.testng.internal.MethodInvocationHelper.invokeMethod(MethodInvocationHelper.java:108)
	at org.testng.internal.Invoker.invokeMethod(Invoker.java:661)
	at org.testng.internal.Invoker.invokeTestMethod(Invoker.java:869)
	at org.testng.internal.TestMethodWithDataProviderMethodWorker.call(TestMethodWithDataProviderMethodWorker.java:75)
	at org.testng.internal.TestMethodWithDataProviderMethodWorker.call(TestMethodWithDataProviderMethodWorker.java:14)
	at java.util.concurrent.FutureTask.run(Unknown Source)
	at java.util.concurrent.Executors$RunnableAdapter.call(Unknown Source)
	at java.util.concurrent.FutureTask.run(Unknown Source)
	at java.util.concurrent.ThreadPoolExecutor.runWorker(Unknown Source)
	at java.util.concurrent.ThreadPoolExecutor$Worker.run(Unknown Source)
	at java.lang.Thread.run(Unknown Source)
]]>
            </full-stacktrace>
          </exception> <!-- java.lang.AssertionError -->
          <reporter-output>
          </reporter-output>
        </test-method> <!-- testCase -->
        <test-method status="PASS" signature="afterClass()[pri:0, instance:com.alg.test.executionengine.Executor@5d624da6]" name="afterClass" is-config="true" duration-ms="776" started-at="2018-02-19T13:43:25Z" finished-at="2018-02-19T13:43:25Z">
          <reporter-output>
          </reporter-output>
        </test-method> <!-- afterClass -->
        <test-method status="PASS" signature="tearDown()[pri:0, instance:com.alg.test.executionengine.Executor@5d624da6]" name="tearDown" is-config="true" duration-ms="0" started-at="2018-02-19T13:43:26Z" finished-at="2018-02-19T13:43:26Z">
          <reporter-output>
          </reporter-output>
        </test-method> <!-- tearDown -->
      </class> <!-- com.alg.test.executionengine.Executor -->
    </test> <!-- Test -->
  </suite> <!-- Regression -->
</testng-results>
